Workbook

Sheet INGRESOS
E1: DIARIO DE INGRESOS
A3: FECHA | B3: NOMBRE | C3: APELLIDO | D3: PRODUCTO | E3: CANTIDAD | F3: PRECIO | G3: INGRESO | H3: DESCRIPCION | I3: OBSERVACION | J3: TIPO DE PAGO | K3: MES | L3: AÑO | M3: ORDEN | N3: SOFFI | O3: Columna1
A4: 46023 | B4: ANTERIOR | E4: 1 | F4: 1993.66 | G4: =E4*F4 -> 1993.66 | H4: CANCELACION | I4: SALDO ANTERIOR DE CAJA | J4: EFECTIVO | K4: =UPPER(TEXT(A4,"MMMM")) -> ENERO | L4: =+YEAR(A4) -> 2026
A5: 46023 | B5: SALDO ANTERIOR | E5: 1 | F5: 445.83 | G5: =E5*F5 -> 445.83 | H5: CANCELACION | J5: PICHINCHA | K5: =UPPER(TEXT(A5,"MMMM")) -> ENERO | L5: =+YEAR(A5) -> 2026
A6: 46027 | B6: ERIK | C6: QUITUISACA | D6: LENTES | E6: 1 | F6: 135 | G6: =E6*F6 -> 135 | H6: CANCELACION | J6: EFECTIVO | K6: =UPPER(TEXT(A6,"MMMM")) -> ENERO | L6: =+YEAR(A6) -> 2026
A7: 46027 | B7: KATERINE | C7: AGUILAR | D7: LENTES | E7: 1 | F7: 25 | G7: =E7*F7 -> 25 | H7: CANCELACION | J7: EFECTIVO | K7: =UPPER(TEXT(A7,"MMMM")) -> ENERO | L7: =+YEAR(A7) -> 2026
A8: 46027 | B8: VIVIANA | C8: SANTOS | D8: LENTES | E8: 1 | F8: 40 | G8: =E8*F8 -> 40 | H8: ABONO | J8: EFECTIVO | K8: =UPPER(TEXT(A8,"MMMM")) -> ENERO | L8: =+YEAR(A8) -> 2026
A9: 46028 | B9: ANAHI | C9: CACERES | D9: CERTIFICADO | E9: 1 | F9: 5 | G9: =E9*F9 -> 5 | H9: CANCELACION | J9: EFECTIVO | K9: =UPPER(TEXT(A9,"MMMM")) -> ENERO | L9: =+YEAR(A9) -> 2026
A10: 46028 | B10: ANAHI | C10: PINOS | D10: LENTES | E10: 1 | F10: 20 | G10: =E10*F10 -> 20 | H10: ABONO | J10: EFECTIVO | K10: =UPPER(TEXT(A10,"MMMM")) -> ENERO | L10: =+YEAR(A10) -> 2026
A11: 46028 | B11: BYRON | C11: AYALA | D11: LENTES | E11: 1 | F11: 160 | G11: =E11*F11 -> 160 | H11: CANCELACION | J11: EFECTIVO | K11: =UPPER(TEXT(A11,"MMMM")) -> ENERO | L11: =+YEAR(A11) -> 2026
A12: 46028 | B12: JOSE | C12: LEON | D12: LENTES | E12: 1 | F12: 216.2 | G12: =E12*F12 -> 216.2 | H12: CANCELACION | J12: EFECTIVO | K12: =UPPER(TEXT(A12,"MMMM")) -> ENERO | L12: =+YEAR(A12) -> 2026
A13: 46028 | B13: NANCY | C13: AMENDAÑO | D13: LENTES | E13: 1 | F13: 10 | G13: =E13*F13 -> 10 | H13: ABONO | J13: EFECTIVO | K13: =UPPER(TEXT(A13,"MMMM")) -> ENERO | L13: =+YEAR(A13) -> 2026
A14: 46028 | B14: VIVIANA | C14: SANTOS | D14: LENTES | E14: 1 | F14: 25 | G14: =E14*F14 -> 25 | H14: CANCELACION | J14: EFECTIVO | K14: =UPPER(TEXT(A14,"MMMM")) -> ENERO | L14: =+YEAR(A14) -> 2026
A15: 46029 | B15: CHRISTIAN | C15: AGUILAR | D15: LENTES | E15: 1 | F15: 50 | G15: =E15*F15 -> 50 | H15: ABONO | J15: EFECTIVO | K15: =UPPER(TEXT(A15,"MMMM")) -> ENERO | L15: =+YEAR(A15) -> 2026
A16: 46029 | B16: LUZ | C16: VASQUEZ | D16: LENTES | E16: 1 | F16: 50 | G16: =E16*F16 -> 50 | H16: ABONO | J16: EFECTIVO | K16: =UPPER(TEXT(A16,"MMMM")) -> ENERO | L16: =+YEAR(A16) -> 2026
A17: 46029 | B17: LUZ | C17: VASQUEZ | D17: LENTES | E17: 1 | F17: 125 | G17: =E17*F17 -> 125 | H17: CANCELACION | J17: PICHINCHA | K17: =UPPER(TEXT(A17,"MMMM")) -> ENERO | L17: =+YEAR(A17) -> 2026
A18: 46029 | B18: NANCY | C18: AMENDAÑO | D18: LENTES | E18: 1 | F18: 30 | G18: =E18*F18 -> 30 | H18: CANCELACION | J18: EFECTIVO | K18: =UPPER(TEXT(A18,"MMMM")) -> ENERO | L18: =+YEAR(A18) -> 2026
A19: 46029 | B19: VARILLAS | C19: VARILLAS | D19: LENTES | E19: 1 | F19: 12 | G19: =E19*F19 -> 12 | H19: CANCELACION | I19: CAMBIO VARILLAS | J19: EFECTIVO | K19: =UPPER(TEXT(A19,"MMMM")) -> ENERO | L19: =+YEAR(A19) -> 2026
A20: 46030 | B20: CERTIFICADO | C20: CARTIFICADO | D20: LENTES | E20: 1 | F20: 5 | G20: =E20*F20 -> 5 | H20: CANCELACION | I20: CERTIFICADO VISUAL | J20: EFECTIVO | K20: =UPPER(TEXT(A20,"MMMM")) -> ENERO | L20: =+YEAR(A20) -> 2026
A21: 46030 | B21: CRUCE DE CUENTAS | E21: 1 | F21: 207 | G21: =E21*F21 -> 207 | H21: CANCELACION | I21: CRUCE DE CUENTAS | J21: PICHINCHA | K21: =UPPER(TEXT(A21,"MMMM")) -> ENERO | L21: =+YEAR(A21) -> 2026
A22: 46030 | B22: FREDDY | C22: RODRIGUEZ | D22: LENTES | E22: 1 | F22: 100 | G22: =E22*F22 -> 100 | H22: ABONO | J22: EFECTIVO | K22: =UPPER(TEXT(A22,"MMMM")) -> ENERO | L22: =+YEAR(A22) -> 2026
A23: 46030 | B23: LAURA | C23: MACAS | D23: LENTES | E23: 1 | F23: 110 | G23: =E23*F23 -> 110 | H23: ABONO | I23: RETIRA LENTES | J23: EFECTIVO | K23: =UPPER(TEXT(A23,"MMMM")) -> ENERO | L23: =+YEAR(A23) -> 2026
A24: 46030 | B24: PAULA | C24: CORONEL | E24: 1 | F24: 13.76 | G24: =E24*F24 -> 13.76 | H24: CANCELACION | I24: SERVICION BASICOS | J24: PICHINCHA | K24: =UPPER(TEXT(A24,"MMMM")) -> ENERO | L24: =+YEAR(A24) -> 2026
A25: 46031 | B25: ANAHI | C25: PINOS | D25: LENTES | E25: 1 | F25: 155 | G25: =E25*F25 -> 155 | H25: CANCELACION | J25: EFECTIVO | K25: =UPPER(TEXT(A25,"MMMM")) -> ENERO | L25: =+YEAR(A25) -> 2026
A26: 46031 | B26: CERTIFICADO | C26: CERTIFICADO | D26: CERTIFICADO | E26: 1 | F26: 5 | G26: =E26*F26 -> 5 | H26: CANCELACION | J26: EFECTIVO | K26: =UPPER(TEXT(A26,"MMMM")) -> ENERO | L26: =+YEAR(A26) -> 2026
A27: 46031 | B27: DAIRA | C27: VILLOTA | D27: LENTES | E27: 1 | F27: 20 | G27: =E27*F27 -> 20 | H27: ABONO | J27: EFECTIVO | K27: =UPPER(TEXT(A27,"MMMM")) -> ENERO | L27: =+YEAR(A27) -> 2026
A28: 46031 | B28: DAYRA | C28: VILLOTA | D28: LENTES | E28: 1 | F28: 80 | G28: =E28*F28 -> 80 | H28: CANCELACION | J28: DE UNA | K28: =UPPER(TEXT(A28,"MMMM")) -> ENERO | L28: =+YEAR(A28) -> 2026
A29: 46031 | B29: JUAN | C29: PADILLA | D29: LENTES | E29: 1 | F29: 79 | G29: =E29*F29 -> 79 | H29: CANCELACION | I29: CREDITO | J29: EFECTIVO | K29: =UPPER(TEXT(A29,"MMMM")) -> ENERO | L29: =+YEAR(A29) -> 2026
A30: 46031 | B30: SEGUNDO | C30: PARDO | D30: LENTES | E30: 1 | F30: 140 | G30: =E30*F30 -> 140 | H30: ABONO | J30: EFECTIVO | K30: =UPPER(TEXT(A30,"MMMM")) -> ENERO | L30: =+YEAR(A30) -> 2026
A31: 46031 | B31: WILSON | C31: CASTRO | D31: LENTES | E31: 1 | F31: 20 | G31: =E31*F31 -> 20 | H31: ABONO | J31: EFECTIVO | K31: =UPPER(TEXT(A31,"MMMM")) -> ENERO | L31: =+YEAR(A31) -> 2026
A32: 46032 | B32: LAURA | C32: RUMIPULLA | D32: LENTES | E32: 1 | F32: 20 | G32: =E32*F32 -> 20 | H32: ABONO | J32: EFECTIVO | K32: =UPPER(TEXT(A32,"MMMM")) -> ENERO | L32: =+YEAR(A32) -> 2026
A33: 46032 | B33: MANUEL | C33: MELGAR | D33: LENTES | E33: 1 | F33: 20 | G33: =E33*F33 -> 20 | H33: ABONO | J33: EFECTIVO | K33: =UPPER(TEXT(A33,"MMMM")) -> ENERO | L33: =+YEAR(A33) -> 2026
A34: 46034 | B34: CERTIFICADO | C34: CERTIFICADO | D34: CERTIFICADO | E34: 1 | F34: 5 | G34: =E34*F34 -> 5 | H34: CANCELACION | J34: EFECTIVO | K34: =UPPER(TEXT(A34,"MMMM")) -> ENERO | L34: =+YEAR(A34) -> 2026
A35: 46035 | B35: CARMEN | C35: ALVARADO | D35: LENTES | E35: 1 | F35: 60 | G35: =E35*F35 -> 60 | H35: ABONO | J35: EFECTIVO | K35: =UPPER(TEXT(A35,"MMMM")) -> ENERO | L35: =+YEAR(A35) -> 2026
A36: 46035 | B36: ILDA | C36: PAUCAR | D36: LENTES | E36: 1 | F36: 60 | G36: =E36*F36 -> 60 | H36: ABONO | J36: EFECTIVO | K36: =UPPER(TEXT(A36,"MMMM")) -> ENERO | L36: =+YEAR(A36) -> 2026
A37: 46035 | B37: JESSICA | C37: PATIÑO | D37: LENTES | E37: 1 | F37: 100 | G37: =E37*F37 -> 100 | H37: ABONO | J37: EFECTIVO | K37: =UPPER(TEXT(A37,"MMMM")) -> ENERO | L37: =+YEAR(A37) -> 2026
A38: 46035 | B38: PIEDAD | C38: BARRERA | D38: LENTES | E38: 1 | F38: 70 | G38: =E38*F38 -> 70 | H38: ABONO | J38: EFECTIVO | K38: =UPPER(TEXT(A38,"MMMM")) -> ENERO | L38: =+YEAR(A38) -> 2026
A39: 46035 | B39: TORNILLO | C39: TORNILLO | D39: ACCESORIOS | E39: 1 | F39: 1 | G39: =E39*F39 -> 1 | H39: CANCELACION | J39: EFECTIVO | K39: =UPPER(TEXT(A39,"MMMM")) -> ENERO | L39: =+YEAR(A39) -> 2026
A40: 46036 | B40: ACCESORIOS | C40: ACCESORIOS | D40: ACCESORIOS | E40: 1 | F40: 8.5 | G40: =E40*F40 -> 8.5 | H40: CANCELACION | I40: ACCESORIOS | J40: EFECTIVO | K40: =UPPER(TEXT(A40,"MMMM")) -> ENERO | L40: =+YEAR(A40) -> 2026
A41: 46036 | B41: CARMEN | C41: ALVARADO | D41: LENTES | E41: 1 | F41: 70 | G41: =E41*F41 -> 70 | H41: CANCELACION | I41: LENTES + PLAQUETAS | J41: EFECTIVO | K41: =UPPER(TEXT(A41,"MMMM")) -> ENERO | L41: =+YEAR(A41) -> 2026
...

Sheet EGRESOS
G1: DIARIO DE EGRESOS
A3: FECHA | B3: CUENTA | C3: DISTRIBUIDOR | D3: CANTIDAD | E3: PRECIO | F3: EGRESO | G3: DETALLE ADICIONAL | H3: NO. DOCUMENTO | I3: MES | J3: AÑO | K3: TIPO DE PAGO | L3: Columna1
A4: 46027 | B4: COMIDA | C4: OTROS | D4: 1 | E4: 7.3 | F4: =Tabla8[[#This Row],[CANTIDAD]]*Tabla8[[#This Row],[PRECIO]] -> 7.3 | G4: FRUTAS | I4: =UPPER(TEXT(A4,"MMMM")) -> ENERO | J4: =+YEAR(A4) -> 2026 | K4: EFECTIVO
A5: 46027 | B5: DANNA | C5: PERSONAL | D5: 1 | E5: 22 | F5: =Tabla8[[#This Row],[CANTIDAD]]*Tabla8[[#This Row],[PRECIO]] -> 22 | G5: ADELANTO DANNA | I5: =UPPER(TEXT(A5,"MMMM")) -> ENERO | J5: =+YEAR(A5) -> 2026 | K5: EFECTIVO
A6: 46027 | B6: BRYAM | C6: PERSONAL | D6: 1 | E6: 15 | F6: =Tabla8[[#This Row],[CANTIDAD]]*Tabla8[[#This Row],[PRECIO]] -> 15 | G6: REGALO AMIGO SECRETO | I6: =UPPER(TEXT(A6,"MMMM")) -> ENERO | J6: =+YEAR(A6) -> 2026 | K6: EFECTIVO
A7: 46027 | B7: DEPOSITO | C7: AHORRO META | D7: 1 | E7: 5 | F7: =Tabla8[[#This Row],[CANTIDAD]]*Tabla8[[#This Row],[PRECIO]] -> 5 | G7: AHORRO META PRODUBANCO | I7: =UPPER(TEXT(A7,"MMMM")) -> ENERO | J7: =+YEAR(A7) -> 2026 | K7: PRODUBANCO
A8: 46027 | B8: DEPOSITO | C8: AHORRO META | D8: 1 | E8: 5 | F8: =Tabla8[[#This Row],[CANTIDAD]]*Tabla8[[#This Row],[PRECIO]] -> 5 | G8: AHORRO META PRODUBANCO | I8: =UPPER(TEXT(A8,"MMMM")) -> ENERO | J8: =+YEAR(A8) -> 2026 | K8: PRODUBANCO
A9: 46027 | B9: DANNA | C9: PERSONAL | D9: 1 | E9: 20 | F9: =Tabla8[[#This Row],[CANTIDAD]]*Tabla8[[#This Row],[PRECIO]] -> 20 | G9: ADELANTO | I9: =UPPER(TEXT(A9,"MMMM")) -> ENERO | J9: =+YEAR(A9) -> 2026 | K9: PICHINCHA
A10: 46027 | B10: COMPRAS | C10: IMPORTLENTS | D10: 1 | E10: 233.47 | F10: =Tabla8[[#This Row],[CANTIDAD]]*Tabla8[[#This Row],[PRECIO]] -> 233.47 | G10: PAGO FACTURAS | I10: =UPPER(TEXT(A10,"MMMM")) -> ENERO | J10: =+YEAR(A10) -> 2026 | K10: PICHINCHA
A11: 46027 | B11: COMPRAS | C11: DELBAK | D11: 1 | E11: 10.93 | F11: =Tabla8[[#This Row],[CANTIDAD]]*Tabla8[[#This Row],[PRECIO]] -> 10.93 | G11: PAGO FACTURAS | I11: =UPPER(TEXT(A11,"MMMM")) -> ENERO | J11: =+YEAR(A11) -> 2026 | K11: PICHINCHA
A12: 46027 | B12: COMPRAS | C12: PROVISION CUENCA | D12: 1 | E12: 68 | F12: =Tabla8[[#This Row],[CANTIDAD]]*Tabla8[[#This Row],[PRECIO]] -> 68 | G12: ARMAZONES | I12: =UPPER(TEXT(A12,"MMMM")) -> ENERO | J12: =+YEAR(A12) -> 2026 | K12: PICHINCHA
A13: 46027 | B13: COMPRAS | C13: TECNILENTS | D13: 1 | E13: 55.61 | F13: =Tabla8[[#This Row],[CANTIDAD]]*Tabla8[[#This Row],[PRECIO]] -> 55.61 | G13: PAGO FACTURAS | I13: =UPPER(TEXT(A13,"MMMM")) -> ENERO | J13: =+YEAR(A13) -> 2026 | K13: PICHINCHA
A14: 46028 | B14: COMPRAS | C14: OTROS | D14: 1 | E14: 73 | F14: =Tabla8[[#This Row],[CANTIDAD]]*Tabla8[[#This Row],[PRECIO]] -> 73 | G14: COMPRAS CORAL CENTRO | I14: =UPPER(TEXT(A14,"MMMM")) -> ENERO | J14: =+YEAR(A14) -> 2026 | K14: EFECTIVO
A15: 46028 | B15: COMPRAS | C15: OTROS | D15: 1 | E15: 3 | F15: =Tabla8[[#This Row],[CANTIDAD]]*Tabla8[[#This Row],[PRECIO]] -> 3 | G15: PAN | I15: =UPPER(TEXT(A15,"MMMM")) -> ENERO | J15: =+YEAR(A15) -> 2026 | K15: EFECTIVO
... A109: 46058 | B109: COMIDA | C109: PERSONAL | D109: 1 | E109: 13.75 | F109: =Tabla8[[#This Row],[CANTIDAD]]*Tabla8[[#This Row],[PRECIO]] -> 13.75 | G109: ALMUERZOS | I109: =UPPER(TEXT(A109,"MMMM")) -> FEBRERO | J109: =+YEAR(A109) -> 2026 | K109: EFECTIVO
A110: 46058 | B110: COMIDA | C110: PERSONAL | D110: 1 | E110: 7.5 | F110: =Tabla8[[#This Row],[CANTIDAD]]*Tabla8[[#This Row],[PRECIO]] -> 7.5 | G110: COMIDA DANNA Y BRYAM | I110: =UPPER(TEXT(A110,"MMMM")) -> FEBRERO | J110: =+YEAR(A110) -> 2026 | K110: PICHINCHA | L110: DE UNA
A111: 46059 | B111: COMPRAS | C111: PROVISION CUENCA | D111: 1 | E111: 27 | F111: =Tabla8[[#This Row],[CANTIDAD]]*Tabla8[[#This Row],[PRECIO]] -> 27 | G111: COMPRAS OPTICA | I111: =UPPER(TEXT(A111,"MMMM")) -> FEBRERO | J111: =+YEAR(A111) -> 2026 | K111: PICHINCHA
A112: 46059 | B112: BRYAM | C112: PERSONAL | D112: 1 | E112: 5 | F112: =Tabla8[[#This Row],[CANTIDAD]]*Tabla8[[#This Row],[PRECIO]] -> 5 | G112: TABLA ZHINDON BRYAM | I112: =UPPER(TEXT(A112,"MMMM")) -> FEBRERO | J112: =+YEAR(A112) -> 2026 | K112: PICHINCHA
A113: 46059 | B113: DEPOSITO | C113: PAGO IESS | D113: 1 | E113: 188.94 | F113: =Tabla8[[#This Row],[CANTIDAD]]*Tabla8[[#This Row],[PRECIO]] -> 188.94 | G113: IESS DANNA Y BRYAM | I113: =UPPER(TEXT(A113,"MMMM")) -> FEBRERO | J113: =+YEAR(A113) -> 2026 | K113: PRODUBANCO
A114: 46059 | B114: COMIDA | C114: PERSONAL | D114: 1 | E114: 23.84 | F114: =Tabla8[[#This Row],[CANTIDAD]]*Tabla8[[#This Row],[PRECIO]] -> 23.84 | G114: COMIDA DANNA Y BRYAM | I114: =UPPER(TEXT(A114,"MMMM")) -> FEBRERO | J114: =+YEAR(A114) -> 2026 | K114: PRODUBANCO
A115: 46059 | B115: DEPOSITO | C115: PAGO IESS COMISION | D115: 1 | E115: 0.31 | F115: =Tabla8[[#This Row],[CANTIDAD]]*Tabla8[[#This Row],[PRECIO]] -> 0.31 | G115: IESS DANNA Y BYRAM COMICION | I115: =UPPER(TEXT(A115,"MMMM")) -> FEBRERO | J115: =+YEAR(A115) -> 2026 | K115: PRODUBANCO
A116: 46059 | B116: COMPRAS | C116: OPTICA | D116: 1 | E116: 27 | F116: =Tabla8[[#This Row],[CANTIDAD]]*Tabla8[[#This Row],[PRECIO]] -> 27 | G116: PROVISION | I116: =UPPER(TEXT(A116,"MMMM")) -> FEBRERO | J116: =+YEAR(A116) -> 2026 | K116: PICHINCHA
A117: 46059 | B117: DANNA | C117: PERSONAL | D117: 1 | E117: 32.5 | F117: =Tabla8[[#This Row],[CANTIDAD]]*Tabla8[[#This Row],[PRECIO]] -> 32.5 | G117: ADELANTO DANNA | I117: =UPPER(TEXT(A117,"MMMM")) -> FEBRERO | J117: =+YEAR(A117) -> 2026 | K117: PICHINCHA
A118: 46059 | B118: DEPOSITO | C118: CRUCE CUENTAS | D118: 1 | E118: 40 | F118: =Tabla8[[#This Row],[CANTIDAD]]*Tabla8[[#This Row],[PRECIO]] -> 40 | G118: CRUCE CUENTAS DE UNA-PICHINCHA | I118: =UPPER(TEXT(A118,"MMMM")) -> FEBRERO | J118: =+YEAR(A118) -> 2026 | K118: PICHINCHA | L118: DE UNA
A119: 46060 | B119: COMIDA | C119: PERSONAL | D119: 1 | E119: 4 | F119: =Tabla8[[#This Row],[CANTIDAD]]*Tabla8[[#This Row],[PRECIO]] -> 4 | G119: MOTO BRYAM | I119: =UPPER(TEXT(A119,"MMMM")) -> FEBRERO | J119: =+YEAR(A119) -> 2026 | K119: EFECTIVO
A120: 46061 | B120: DANNA | C120: PERSONAL | D120: 1 | E120: 30 | F120: =Tabla8[[#This Row],[CANTIDAD]]*Tabla8[[#This Row],[PRECIO]] -> 30 | G120: ADELANTO DANNA | I120: =UPPER(TEXT(A120,"MMMM")) -> FEBRERO | J120: =+YEAR(A120) -> 2026 | K120: EFECTIVO
A121: 46062 | B121: COMIDA | C121: PERSONAL | D121: 1 | E121: 2.5 | F121: =Tabla8[[#This Row],[CANTIDAD]]*Tabla8[[#This Row],[PRECIO]] -> 2.5 | G121: COMIDA DANNA Y BRYAM | I121: =UPPER(TEXT(A121,"MMMM")) -> FEBRERO | J121: =+YEAR(A121) -> 2026 | K121: PICHINCHA | L121: DE UNA
A122: 46063 | B122: DEPOSITO | C122: OPTICA | D122: 1 | E122: 50 | F122: =Tabla8[[#This Row],[CANTIDAD]]*Tabla8[[#This Row],[PRECIO]] -> 50 | G122: DEPOSITO BANCO | I122: =UPPER(TEXT(A122,"MMMM")) -> FEBRERO | J122: =+YEAR(A122) -> 2026 | K122: EFECTIVO
A123: 46063 | B123: COMPRAS | C123: OPTICA | D123: 1 | E123: 6.21 | F123: =Tabla8[[#This Row],[CANTIDAD]]*Tabla8[[#This Row],[PRECIO]] -> 6.21 | G123: COMPRAS CYC | I123: =UPPER(TEXT(A123,"MMMM")) -> FEBRERO | J123: =+YEAR(A123) -> 2026 | K123: PICHINCHA
A124: 46065 | B124: COMIDA | C124: PERSONAL | D124: 1 | E124: 5 | F124: =Tabla8[[#This Row],[CANTIDAD]]*Tabla8[[#This Row],[PRECIO]] -> 5 | G124: COMIAD FRUTAS | I124: =UPPER(TEXT(A124,"MMMM")) -> FEBRERO | J124: =+YEAR(A124) -> 2026 | K124: EFECTIVO
A125: 46065 | B125: BRYAM | C125: PERSONAL | D125: 1 | E125: 40 | F125: =Tabla8[[#This Row],[CANTIDAD]]*Tabla8[[#This Row],[PRECIO]] -> 40 | G125: ADELANTO BRYAM | I125: =UPPER(TEXT(A125,"MMMM")) -> FEBRERO | J125: =+YEAR(A125) -> 2026 | K125: EFECTIVO
A126: 46065 | B126: COMIDA | C126: PERSONAL | D126: 1 | E126: 1.2 | F126: =Tabla8[[#This Row],[CANTIDAD]]*Tabla8[[#This Row],[PRECIO]] -> 1.2 | G126: COMIDA | I126: =UPPER(TEXT(A126,"MMMM")) -> FEBRERO | J126: =+YEAR(A126) -> 2026 | K126: EFECTIVO
A127: 46065 | B127: DANNA | C127: PERSONAL | D127: 1 | E127: 15 | F127: =Tabla8[[#This Row],[CANTIDAD]]*Tabla8[[#This Row],[PRECIO]] -> 15 | G127: ADELANTO DANNA | I127: =UPPER(TEXT(A127,"MMMM")) -> FEBRERO | J127: =+YEAR(A127) -> 2026 | K127: PICHINCHA
A128: 46066 | B128: COMPRAS | C128: OPTICA | D128: 1 | E128: 18 | F128: =Tabla8[[#This Row],[CANTIDAD]]*Tabla8[[#This Row],[PRECIO]] -> 18 | G128: COSAS DE LIMPIEZA | I128: =UPPER(TEXT(A128,"MMMM")) -> FEBRERO | J128: =+YEAR(A128) -> 2026 | K128: EFECTIVO
A129: 46066 | B129: BRYAM | C129: PERSONAL | D129: 1 | E129: 4 | F129: =Tabla8[[#This Row],[CANTIDAD]]*Tabla8[[#This Row],[PRECIO]] -> 4 | G129: ADELANTO BRYAM | I129: =UPPER(TEXT(A129,"MMMM")) -> FEBRERO | J129: =+YEAR(A129) -> 2026 | K129: EFECTIVO
A130: 46066 | B130: DANNA | C130: PERSONAL | D130: 1 | E130: 18 | F130: =Tabla8[[#This Row],[CANTIDAD]]*Tabla8[[#This Row],[PRECIO]] -> 18 | G130: ADELANTO DANNA | I130: =UPPER(TEXT(A130,"MMMM")) -> FEBRERO | J130: =+YEAR(A130) -> 2026 | K130: PICHINCHA
A131: 46066 | B131: COMIDA | C131: PERSONAL | D131: 1 | E131: 10 | F131: =Tabla8[[#This Row],[CANTIDAD]]*Tabla8[[#This Row],[PRECIO]] -> 10 | G131: ALMUERZO DANNA Y BRYAM | I131: =UPPER(TEXT(A131,"MMMM")) -> FEBRERO | J131: =+YEAR(A131) -> 2026 | K131: EFECTIVO
A132: 46066 | B132: BRYAM | C132: PERSONAL | D132: 1 | E132: 1 | F132: =Tabla8[[#This Row],[CANTIDAD]]*Tabla8[[#This Row],[PRECIO]] -> 1 | G132: BRYAM | I132: =UPPER(TEXT(A132,"MMMM")) -> FEBRERO | J132: =+YEAR(A132) -> 2026 | K132: EFECTIVO
A133: 46066 | B133: COMIDA | C133: PERSONAL | D133: 1 | E133: 20 | F133: =Tabla8[[#This Row],[CANTIDAD]]*Tabla8[[#This Row],[PRECIO]] -> 20 | G133: ALMUERZO DANNA Y BRYAM | I133: =UPPER(TEXT(A133,"MMMM")) -> FEBRERO | J133: =+YEAR(A133) -> 2026 | K133: EFECTIVO
... A136: 46067 | B136: MOTORIZADO | C136: OPTICA | D136: 1 | E136: 2 | F136: =Tabla8[[#This Row],[CANTIDAD]]*Tabla8[[#This Row],[PRECIO]] -> 2 | G136: MOTO BRYAM | I136: =UPPER(TEXT(A136,"MMMM")) -> FEBRERO | J136: =+YEAR(A136) -> 2026 | K136: EFECTIVO
...

Sheet FACTURAS
E1: DIARIO DE FACTURAS
A3: FECHA | B3: CUENTA | C3: DISTRIBUIDOR | D3: TOTAL | E3: DETALLE ADICIONAL | F3: NO. DOCUMENTO | G3: MES | H3: AÑO | I3: TIPO DE PAGO
A4: 46028 | B4: POR PAGAR | C4: IMPORTLENTS | D4: 25.9 | E4: LUNAS Y BISEL PARA JOSE LEON | F4: 62352 | G4: =UPPER(TEXT(A4,"MMMM")) -> ENERO | H4: =+YEAR(A4) -> 2026
A5: 46028 | B5: POR PAGAR | C5: IMPORTLENTS | D5: 31.51 | E5: LUNAS Y BISEL PARA BYRON AYALA | F5: 62355 | G5: =UPPER(TEXT(A5,"MMMM")) -> ENERO | H5: =+YEAR(A5) -> 2026
A6: 46029 | B6: POR PAGAR | C6: IMPORTLENTS | D6: 29.26 | E6: LUNAS Y BISEL PARA ANAHI PINOS | F6: 62416 | G6: =UPPER(TEXT(A6,"MMMM")) -> ENERO | H6: =+YEAR(A6) -> 2026
A7: 46029 | B7: POR PAGAR | C7: IMPORTLENTS | D7: 31.35 | E7: LUNAS Y BISEL NANCY AMENDAÑO Y FABIAN MARIN | F7: 62425 | G7: =UPPER(TEXT(A7,"MMMM")) -> ENERO | H7: =+YEAR(A7) -> 2026
A8: 46029 | B8: POR PAGAR | C8: IMPORTLENTS | D8: 23.9 | E8: LUNAS LUZ VASQUEZ | F8: 62427 | G8: =UPPER(TEXT(A8,"MMMM")) -> ENERO | H8: =+YEAR(A8) -> 2026
A9: 46030 | B9: POR PAGAR | C9: OPTEC | D9: 24.15 | E9: LUNA TERMINADA TRANSITION GRIS DAVID RODRIGUEZ | F9: 928780 | G9: =UPPER(TEXT(A9,"MMMM")) -> ENERO | H9: =+YEAR(A9) -> 2026
A10: 46030 | B10: POR PAGAR | C10: OPTEC | D10: 41.4 | E10: LUNA TALLADA TRANSITION GRIS DAVID RODRIGUEZ | F10: 92782 | G10: =UPPER(TEXT(A10,"MMMM")) -> ENERO | H10: =+YEAR(A10) -> 2026
A11: 46031 | B11: POR PAGAR | C11: IMPORTLENTS | D11: 2.1 | E11: BISEL | F11: 62552 | G11: =UPPER(TEXT(A11,"MMMM")) -> ENERO | H11: =+YEAR(A11) -> 2026
A12: 46031 | B12: PAGADO | C12: PECSA | D12: 52.23 | E12: LUNAS PECSA PRECISA BLUE +AR EULALIA GALINDO | F12: 2354 | G12: =UPPER(TEXT(A12,"MMMM")) -> ENERO | H12: =+YEAR(A12) -> 2026
A13: 46032 | B13: POR PAGAR | C13: IMPORTLENTS | D13: 2.6 | E13: BISEL BIFOCAL | F13: 62590 | G13: =UPPER(TEXT(A13,"MMMM")) -> ENERO | H13: =+YEAR(A13) -> 2026
A14: 46034 | B14: POR PAGAR | C14: IMPORTLENTS | D14: 1 | E14: BISEL | F14: 62630 | G14: =UPPER(TEXT(A14,"MMMM")) -> ENERO | H14: =+YEAR(A14) -> 2026
A15: 46034 | B15: POR PAGAR | C15: IMPORTLENTS | D15: 27 | E15: LUNAS Y BISEL VANESSA PESANTEZ | F15: 62660 | G15: =UPPER(TEXT(A15,"MMMM")) -> ENERO | H15: =+YEAR(A15) -> 2026
... A43: 46058 | B43: POR PAGAR | C43: IMPORTLENTS | D43: 20.52 | E43: LUNAS POLI AR- LUIS BRAVO | F43: 63735 | G43: =UPPER(TEXT(A43,"MMMM")) -> FEBRERO | H43: =+YEAR(A43) -> 2026
A44: 46058 | B44: POR PAGAR | C44: IMPORTLENTS | D44: * | E44: LUNAS AR - PAUL SUÑA | F44: 63735 | G44: =UPPER(TEXT(A44,"MMMM")) -> FEBRERO | H44: =+YEAR(A44) -> 2026
A45: 46059 | B45: POR PAGAR | C45: IMPORTLENTS | D45: 2.4 | E45: LUNAS BLUE AR | F45: 63809 | G45: =UPPER(TEXT(A45,"MMMM")) -> FEBRERO | H45: =+YEAR(A45) -> 2026
A46: 46059 | B46: POR PAGAR | C46: IMPORTLENTS | D46: 5.41 | E46: LUNAS POLY AR AMELIA MOGROVEJO | F46: 63785 | G46: =UPPER(TEXT(A46,"MMMM")) -> FEBRERO | H46: =+YEAR(A46) -> 2026
A47: 46059 | B47: POR PAGAR | C47: OPTEC | D47: 55.2 | E47: LUNAS-POLI-POLARIZADO- MIRIAM SEGOVIA | F47: 939548 | G47: =UPPER(TEXT(A47,"MMMM")) -> FEBRERO | H47: =+YEAR(A47) -> 2026
A48: 46060 | B48: POR PAGAR | C48: IMPORTLENTS | D48: 5.41 | E48: LUNAS POLI AR-ROSA AREVALO | F48: 63871 | G48: =UPPER(TEXT(A48,"MMMM")) -> FEBRERO | H48: =+YEAR(A48) -> 2026
A49: 46063 | B49: POR PAGAR | C49: IMPORTLENTS | D49: 3.99 | E49: BISEL POLY BLANCO Y TRASPASO | F49: 63974 | G49: =UPPER(TEXT(A49,"MMMM")) -> FEBRERO | H49: =+YEAR(A49) -> 2026
A50: 46065 | B50: POR PAGAR | C50: IMPORTLENTS | D50: * | E50: LUNAS ANTIREFLEJO ROCIO LITUMA Y BISEL | F50: 54053 | G50: =UPPER(TEXT(A50,"MMMM")) -> FEBRERO | H50: =+YEAR(A50) -> 2026
A51: 46065 | B51: POR PAGAR | C51: IMPORTLENTS | D51: 9.89 | E51: ARM. METAL CRONOS Y TRASPASO | F51: 54058 | G51: =UPPER(TEXT(A51,"MMMM")) -> FEBRERO | H51: =+YEAR(A51) -> 2026
A52: 46067 | B52: POR PAGAR | C52: IMPORTLENTS | D52: 62.01 | E52: LUNAS Y BISEL PEDRO CHALCO GX7 (4 LUNAS) | F52: 54142 | G52: =UPPER(TEXT(A52,"MMMM")) -> FEBRERO | H52: =+YEAR(A52) -> 2026
A53: 46067 | B53: POR PAGAR | C53: IMPORTLENTS | D53: * | E53: TRASPASO | F53: 54142 | G53: =UPPER(TEXT(A53,"MMMM")) -> FEBRERO | H53: =+YEAR(A53) -> 2026
A54: 46071 | B54: POR PAGAR | C54: OPTEC | D54: 115 | E54: LUNAS POLI-PRO KODAK ZAFIRO-BERTHA GUILLEN | F54: 942678 | G54: =UPPER(TEXT(A54,"MMMM")) -> FEBRERO | H54: =+YEAR(A54) -> 2026
A55: 46072 | B55: POR PAGAR | C55: IMPORTLENTS | D55: 13.31 | E55: BISELADOS GX7 Y POLY BLUE AR | F55: 10013571 | G55: =UPPER(TEXT(A55,"MMMM")) -> FEBRERO | H55: =+YEAR(A55) -> 2026
A56: 46072 | B56: PAGADO | C56: PECSA | D56: 46.21 | E56: PROGRESIVO BLUE BLOCK + AR -EDUARDO CANDO | F56: 81002 | G56: =UPPER(TEXT(A56,"MMMM")) -> FEBRERO | H56: =+YEAR(A56) -> 2026
A57: 46072 | B57: PAGADO | C57: PECSA | D57: 51.21 | E57: PROGRESIVO BLUE BLOCK + AR -EDUARDO CANDO | F57: 81001 | G57: =UPPER(TEXT(A57,"MMMM")) -> FEBRERO | H57: =+YEAR(A57) -> 2026
A58: 46073 | B58: POR PAGAR | C58: IMPORTLENTS | D58: 22.1 | E58: LUNAS FABIO MOROCHO GX7 BLUE AR Y BISEL | F58: 10013590 | G58: =UPPER(TEXT(A58,"MMMM")) -> FEBRERO | H58: =+YEAR(A58) -> 2026
A59: 46073 | B59: POR PAGAR | C59: IMPORTLENTS | D59: 27 | E59: LUNAS GX7 BLUE AR MICHELLE ZAMORA | F59: 10013603 | G59: =UPPER(TEXT(A59,"MMMM")) -> FEBRERO | H59: =+YEAR(A59) -> 2026
A60: 46073 | B60: POR PAGAR | C60: IMPORTLENTS | D60: 11.01 | E60: L/C VERDE - DAYANA MOROCHO | F60: 10013604 | G60: =UPPER(TEXT(A60,"MMMM")) -> FEBRERO | H60: =+YEAR(A60) -> 2026
A61: 46074 | B61: PAGADO | C61: PROVISION LENS | D61: 10 | E61: LUNAS POLY-BLANCO - JUAN DIEGO MOROCHO | F61: 8565 | G61: =UPPER(TEXT(A61,"MMMM")) -> FEBRERO | H61: =+YEAR(A61) -> 2026
A62: 46077 | B62: POR PAGAR | C62: OPTEC | D62: 110.4 | E62: LUNAS POLI VARILUX BLUE AR- HUMBERTO PARRAGA | F62: 945145 | G62: =UPPER(TEXT(A62,"MMMM")) -> FEBRERO | H62: =+YEAR(A62) -> 2026
A63: 46079 | B63: POR PAGAR | C63: IMPORTLENTS | D63: 7.05 | E63: LUNAS POLI-AR - ANDRES LEON | F63: 13684 | G63: =UPPER(TEXT(A63,"MMMM")) -> FEBRERO | H63: =+YEAR(A63) -> 2026
A64: 46079 | B64: PAGADO | C64: PECSA | D64: 46.21 | E64: LUNAS PROGRESIVAS BLUE + AR- SANTIAGO ESPINOZA | F64: 3798 | G64: =UPPER(TEXT(A64,"MMMM")) -> FEBRERO | H64: =+YEAR(A64) -> 2026
A65: 46079 | B65: PAGADO | C65: PECSA | D65: 41.07 | E65: PROGRESIVAS ELITE HD BLUE+AR- SORAYA CRIOLLO | F65: 3800 | G65: =UPPER(TEXT(A65,"MMMM")) -> FEBRERO | H65: =+YEAR(A65) -> 2026
... A67: 46079 | B67: PAGADO | C67: PECSA | D67: 46.21 | E67: PROGRESIVAS BLUE BLOCK + AR-EDGAR GUY | F67: 3799 | G67: =UPPER(TEXT(A67,"MMMM")) -> FEBRERO | H67: =+YEAR(A67) -> 2026
A68: 46083 | G68: =UPPER(TEXT(A68,"MMMM")) -> MARZO | H68: =+YEAR(A68) -> 2026
A69: 46084 | B69: POR PAGAR | C69: IMPORTLENTS | D69: 23.9 | E69: GX7-BLUE AR-ERIKA ARIAS | F69: 64776 | G69: =UPPER(TEXT(A69,"MMMM")) -> MARZO | H69: =+YEAR(A69) -> 2026
...

Sheet RESUMEN 1
A3: AÑO | B3: REGISTRO DE INGRESOS Y EGRESOS
A5: 2026 | B5: TIPO | C5: ENERO | D5: FEBRERO | E5: MARZO | F5: ABRIL | G5: MAYO | H5: JUNIO | I5: JULIO | J5: AGOSTO | K5: SEPTIEMBRE | L5: OCTUBRE | M5: NOVIEMBRE | N5: DICIEMBRE
A6: INGRESOS | B6: EFECTIVO | C6: =SUMIFS(Tabla5[INGRESO],Tabla5[MES],'RESUMEN 1'!C5,Tabla5[AÑO],'RESUMEN 1'!A5,Tabla5[TIPO DE PAGO],'RESUMEN 1'!B6) -> 6101.86 | D6: =SUMIFS(Tabla5[INGRESO],Tabla5[MES],'RESUMEN 1'!D5,Tabla5[AÑO],'RESUMEN 1'!A5,Tabla5[TIPO DE PAGO],'RESUMEN 1'!B6) -> 2220 | L6: =SUMIFS(Tabla5[INGRESO],Tabla5[MES],'RESUMEN 1'!L5,Tabla5[AÑO],'RESUMEN 1'!A5,Tabla5[TIPO DE PAGO],'RESUMEN 1'!B6) -> 0 | M6: =SUMIFS(Tabla5[INGRESO],Tabla5[MES],'RESUMEN 1'!M5,Tabla5[AÑO],'RESUMEN 1'!A5,Tabla5[TIPO DE PAGO],'RESUMEN 1'!B6) -> 0
A7: INGRESOS | B7: TARJETA | C7: =SUMIFS(Tabla5[INGRESO],Tabla5[MES],'RESUMEN 1'!C5,Tabla5[AÑO],'RESUMEN 1'!A5,Tabla5[TIPO DE PAGO],'RESUMEN 1'!B7) -> 0 | L7: =SUMIFS(Tabla5[INGRESO],Tabla5[MES],'RESUMEN 1'!L5,Tabla5[AÑO],'RESUMEN 1'!A5,Tabla5[TIPO DE PAGO],'RESUMEN 1'!B7) -> 0 | M7: =SUMIFS(Tabla5[INGRESO],Tabla5[MES],'RESUMEN 1'!M5,Tabla5[AÑO],'RESUMEN 1'!A5,Tabla5[TIPO DE PAGO],'RESUMEN 1'!B7) -> 0
A8: INGRESOS | B8: JEP DANNA | C8: =SUMIFS(Tabla5[INGRESO],Tabla5[MES],'RESUMEN 1'!C5,Tabla5[AÑO],'RESUMEN 1'!A5,Tabla5[TIPO DE PAGO],'RESUMEN 1'!B8)+SUMIFS(Tabla8[EGRESO],Tabla8[CUENTA],"DEPOSITO",Tabla8[DISTRIBUIDOR],'RESUMEN 1'!B8) -> 50 | D8: =SUMIFS(Tabla5[INGRESO],Tabla5[MES],'RESUMEN 1'!D5,Tabla5[AÑO],'RESUMEN 1'!A5,Tabla5[TIPO DE PAGO],'RESUMEN 1'!B8)+SUMIFS(Tabla8[EGRESO],Tabla8[CUENTA],"DEPOSITO",Tabla8[DISTRIBUIDOR],'RESUMEN 1'!B8) -> 396.76 | L8: =SUMIFS(Tabla5[INGRESO],Tabla5[MES],'RESUMEN 1'!L5,Tabla5[AÑO],'RESUMEN 1'!A5,Tabla5[TIPO DE PAGO],'RESUMEN 1'!B8) -> 0 | M8: =SUMIFS(Tabla5[INGRESO],Tabla5[MES],'RESUMEN 1'!M5,Tabla5[AÑO],'RESUMEN 1'!A5,Tabla5[TIPO DE PAGO],'RESUMEN 1'!B8) -> 0
A9: INGRESOS | B9: PICHINCHA | C9: =SUMIFS(Tabla5[INGRESO],Tabla5[MES],'RESUMEN 1'!C5,Tabla5[AÑO],'RESUMEN 1'!A5,Tabla5[TIPO DE PAGO],'RESUMEN 1'!B9)+SUMIFS(Tabla8[EGRESO],Tabla8[CUENTA],"DEPOSITO",Tabla8[DISTRIBUIDOR],'RESUMEN 1'!B9) -> 1891.59 | D9: =SUMIFS(Tabla5[INGRESO],Tabla5[MES],'RESUMEN 1'!D5,Tabla5[AÑO],'RESUMEN 1'!A5,Tabla5[TIPO DE PAGO],'RESUMEN 1'!B9)+SUMIFS(Tabla8[EGRESO],Tabla8[CUENTA],"DEPOSITO",Tabla8[DISTRIBUIDOR],'RESUMEN 1'!B9) -> 1534.43 | L9: =SUMIFS(Tabla5[INGRESO],Tabla5[MES],'RESUMEN 1'!L5,Tabla5[AÑO],'RESUMEN 1'!A5,Tabla5[TIPO DE PAGO],'RESUMEN 1'!B9) -> 0 | M9: =SUMIFS(Tabla5[INGRESO],Tabla5[MES],'RESUMEN 1'!M5,Tabla5[AÑO],'RESUMEN 1'!A5,Tabla5[TIPO DE PAGO],'RESUMEN 1'!B9) -> 0
A10: INGRESOS | B10: PRODUBANCO | C10: =SUMIFS(Tabla5[INGRESO],Tabla5[MES],'RESUMEN 1'!C5,Tabla5[AÑO],'RESUMEN 1'!A5,Tabla5[TIPO DE PAGO],'RESUMEN 1'!B10)+SUMIFS(Tabla8[EGRESO],Tabla8[CUENTA],"DEPOSITO",Tabla8[DISTRIBUIDOR],'RESUMEN 1'!B10) -> 0 | L10: =SUMIFS(Tabla5[INGRESO],Tabla5[MES],'RESUMEN 1'!L5,Tabla5[AÑO],'RESUMEN 1'!A5,Tabla5[TIPO DE PAGO],'RESUMEN 1'!B10) -> 0 | M10: =SUMIFS(Tabla5[INGRESO],Tabla5[MES],'RESUMEN 1'!M5,Tabla5[AÑO],'RESUMEN 1'!A5,Tabla5[TIPO DE PAGO],'RESUMEN 1'!B10) -> 0
A11: INGRESOS | B11: JARDIN AZUAYO | C11: =SUMIFS(Tabla5[INGRESO],Tabla5[MES],'RESUMEN 1'!C5,Tabla5[AÑO],'RESUMEN 1'!A5,Tabla5[TIPO DE PAGO],'RESUMEN 1'!B11)+SUMIFS(Tabla8[EGRESO],Tabla8[CUENTA],"DEPOSITO",Tabla8[DISTRIBUIDOR],'RESUMEN 1'!B11) -> 0 | L11: =SUMIFS(Tabla5[DESCRIPCION],Tabla5[AÑO],'RESUMEN 1'!L5,Tabla5[FECHA],'RESUMEN 1'!A5,Tabla5[MES],'RESUMEN 1'!B11) -> 0 | M11: =SUMIFS(Tabla5[DESCRIPCION],Tabla5[AÑO],'RESUMEN 1'!M5,Tabla5[FECHA],'RESUMEN 1'!A5,Tabla5[MES],'RESUMEN 1'!B11) -> 0
A12: INGRESOS | B12: JEP BRYAM | C12: =SUMIFS(Tabla5[INGRESO],Tabla5[MES],'RESUMEN 1'!C5,Tabla5[AÑO],'RESUMEN 1'!A5,Tabla5[TIPO DE PAGO],'RESUMEN 1'!B12)+SUMIFS(Tabla8[EGRESO],Tabla8[CUENTA],"DEPOSITO",Tabla8[DISTRIBUIDOR],'RESUMEN 1'!B12) -> 0 | L12: =SUMIFS(Tabla5[INGRESO],Tabla5[MES],'RESUMEN 1'!L5,Tabla5[AÑO],'RESUMEN 1'!A5,Tabla5[TIPO DE PAGO],'RESUMEN 1'!B12) -> 0 | M12: =SUMIFS(Tabla5[INGRESO],Tabla5[MES],'RESUMEN 1'!M5,Tabla5[AÑO],'RESUMEN 1'!A5,Tabla5[TIPO DE PAGO],'RESUMEN 1'!B12) -> 0
A15: GASTOS | B15: EFECTIVO | C15: =SUMIFS(Tabla8[EGRESO],Tabla8[MES],'RESUMEN 1'!C5,Tabla8[AÑO],'RESUMEN 1'!A5,Tabla8[TIPO DE PAGO],'RESUMEN 1'!B15) -> 1758.15 | D15: =SUMIFS(Tabla8[EGRESO],Tabla8[MES],'RESUMEN 1'!D5,Tabla8[AÑO],'RESUMEN 1'!A5,Tabla8[TIPO DE PAGO],'RESUMEN 1'!B15) -> 1543.13 | L15: =SUMIFS(Tabla8[EGRESO],Tabla8[MES],'RESUMEN 1'!L5,Tabla8[AÑO],'RESUMEN 1'!A5,Tabla8[TIPO DE PAGO],'RESUMEN 1'!B15) -> 0 | M15: =SUMIFS(Tabla8[EGRESO],Tabla8[MES],'RESUMEN 1'!M5,Tabla8[AÑO],'RESUMEN 1'!A5,Tabla8[TIPO DE PAGO],'RESUMEN 1'!B15) -> 0
A16: GASTOS | B16: TARJETA | L16: =SUMIFS(Tabla8[EGRESO],Tabla8[MES],'RESUMEN 1'!L5,Tabla8[AÑO],'RESUMEN 1'!A5,Tabla8[TIPO DE PAGO],'RESUMEN 1'!B16) -> 0 | M16: =SUMIFS(Tabla8[EGRESO],Tabla8[MES],'RESUMEN 1'!M5,Tabla8[AÑO],'RESUMEN 1'!A5,Tabla8[TIPO DE PAGO],'RESUMEN 1'!B16) -> 0
A17: GASTOS | B17: JEP DANNA | C17: =SUMIFS(Tabla8[EGRESO],Tabla8[MES],'RESUMEN 1'!C5,Tabla8[AÑO],'RESUMEN 1'!A5,Tabla8[TIPO DE PAGO],'RESUMEN 1'!B17) -> 0 | L17: =SUMIFS(Tabla8[EGRESO],Tabla8[MES],'RESUMEN 1'!L5,Tabla8[AÑO],'RESUMEN 1'!A5,Tabla8[TIPO DE PAGO],'RESUMEN 1'!B17) -> 0 | M17: =SUMIFS(Tabla8[EGRESO],Tabla8[MES],'RESUMEN 1'!M5,Tabla8[AÑO],'RESUMEN 1'!A5,Tabla8[TIPO DE PAGO],'RESUMEN 1'!B17) -> 0
A18: GASTOS | B18: PICHINCHA | C18: =SUMIFS(Tabla8[EGRESO],Tabla8[MES],'RESUMEN 1'!C5,Tabla8[AÑO],'RESUMEN 1'!A5,Tabla8[TIPO DE PAGO],'RESUMEN 1'!B18) -> 2080.83 | L18: =SUMIFS(Tabla8[EGRESO],Tabla8[MES],'RESUMEN 1'!L5,Tabla8[AÑO],'RESUMEN 1'!A5,Tabla8[TIPO DE PAGO],'RESUMEN 1'!B18) -> 0 | M18: =SUMIFS(Tabla8[EGRESO],Tabla8[MES],'RESUMEN 1'!M5,Tabla8[AÑO],'RESUMEN 1'!A5,Tabla8[TIPO DE PAGO],'RESUMEN 1'!B18) -> 0
A19: GASTOS | B19: PRODUBANCO | L19: =SUMIFS(Tabla8[EGRESO],Tabla8[MES],'RESUMEN 1'!L5,Tabla8[AÑO],'RESUMEN 1'!A5,Tabla8[TIPO DE PAGO],'RESUMEN 1'!B19) -> 0 | M19: =SUMIFS(Tabla8[EGRESO],Tabla8[MES],'RESUMEN 1'!M5,Tabla8[AÑO],'RESUMEN 1'!A5,Tabla8[TIPO DE PAGO],'RESUMEN 1'!B19) -> 0
A20: GASTOS | B20: JARDIN AZUAYO | L20: =SUMIFS(Tabla8[EGRESO],Tabla8[MES],'RESUMEN 1'!L5,Tabla8[AÑO],'RESUMEN 1'!A5,Tabla8[TIPO DE PAGO],'RESUMEN 1'!B20) -> 0 | M20: =SUMIFS(Tabla8[EGRESO],Tabla8[MES],'RESUMEN 1'!M5,Tabla8[AÑO],'RESUMEN 1'!A5,Tabla8[TIPO DE PAGO],'RESUMEN 1'!B20) -> 0
A21: GASTOS | B21: JEP BRYAM | L21: =SUMIFS(Tabla8[EGRESO],Tabla8[MES],'RESUMEN 1'!L5,Tabla8[AÑO],'RESUMEN 1'!A5,Tabla8[TIPO DE PAGO],'RESUMEN 1'!B21) -> 0 | M21: =SUMIFS(Tabla8[EGRESO],Tabla8[MES],'RESUMEN 1'!M5,Tabla8[AÑO],'RESUMEN 1'!A5,Tabla8[TIPO DE PAGO],'RESUMEN 1'!B21) -> 0
A22: GASTOS | B22: BRYAM | C22: =SUMIFS(Tabla8[EGRESO],Tabla8[MES],'RESUMEN 1'!C5,Tabla8[AÑO],'RESUMEN 1'!A5,Tabla8[CUENTA],'RESUMEN 1'!B22) -> 55 | D22: =SUMIFS(Tabla8[EGRESO],Tabla8[MES],'RESUMEN 1'!D5,Tabla8[AÑO],'RESUMEN 1'!A5,Tabla8[CUENTA],'RESUMEN 1'!B22) -> 50 | L22: =SUMIFS(Tabla8[EGRESO],Tabla8[MES],'RESUMEN 1'!L6,Tabla8[AÑO],'RESUMEN 1'!A6,Tabla8[TIPO DE PAGO],'RESUMEN 1'!B22) -> 0 | M22: =SUMIFS(Tabla8[EGRESO],Tabla8[MES],'RESUMEN 1'!M6,Tabla8[AÑO],'RESUMEN 1'!A6,Tabla8[TIPO DE PAGO],'RESUMEN 1'!B22) -> 0
A23: GASTOS | B23: DANNA | C23: =SUMIFS(Tabla8[EGRESO],Tabla8[MES],'RESUMEN 1'!C5,Tabla8[AÑO],'RESUMEN 1'!A5,Tabla8[CUENTA],'RESUMEN 1'!B23) -> 181.34 | D23: =SUMIFS(Tabla8[EGRESO],Tabla8[MES],'RESUMEN 1'!D5,Tabla8[AÑO],'RESUMEN 1'!A5,Tabla8[CUENTA],'RESUMEN 1'!B23) -> 194.5 | L23: =SUMIFS(Tabla8[EGRESO],Tabla8[MES],'RESUMEN 1'!L7,Tabla8[AÑO],'RESUMEN 1'!A7,Tabla8[TIPO DE PAGO],'RESUMEN 1'!B23) -> 0 | M23: =SUMIFS(Tabla8[EGRESO],Tabla8[MES],'RESUMEN 1'!M7,Tabla8[AÑO],'RESUMEN 1'!A7,Tabla8[TIPO DE PAGO],'RESUMEN 1'!B23) -> 0
A26: POR PAGAR | B26: IMPORTLENTS | C26: =SUMIFS(Tabla6[TOTAL],Tabla6[MES],'RESUMEN 1'!C5,Tabla6[AÑO],'RESUMEN 1'!A5,Tabla6[DISTRIBUIDOR],'RESUMEN 1'!B26) -> 433.51 | D26: =SUMIFS(Tabla6[TOTAL],Tabla6[MES],'RESUMEN 1'!D5,Tabla6[AÑO],'RESUMEN 1'!A5,Tabla6[DISTRIBUIDOR],'RESUMEN 1'!B26) -> 212.59 | E26: =SUMIFS(Tabla6[TOTAL],Tabla6[MES],'RESUMEN 1'!E5,Tabla6[AÑO],'RESUMEN 1'!A5,Tabla6[DISTRIBUIDOR],'RESUMEN 1'!B26) -> 23.9 | F26: =SUMIFS(Tabla6[TOTAL],Tabla6[MES],'RESUMEN 1'!F5,Tabla6[AÑO],'RESUMEN 1'!A5,Tabla6[DISTRIBUIDOR],'RESUMEN 1'!B26) -> 0 | G26: =SUMIFS(Tabla6[TOTAL],Tabla6[MES],'RESUMEN 1'!G5,Tabla6[AÑO],'RESUMEN 1'!A5,Tabla6[DISTRIBUIDOR],'RESUMEN 1'!B26) -> 0 | H26: =SUMIFS(Tabla6[TOTAL],Tabla6[MES],'RESUMEN 1'!H5,Tabla6[AÑO],'RESUMEN 1'!A5,Tabla6[DISTRIBUIDOR],'RESUMEN 1'!B26) -> 0 | I26: =SUMIFS(Tabla6[TOTAL],Tabla6[MES],'RESUMEN 1'!I5,Tabla6[AÑO],'RESUMEN 1'!A5,Tabla6[DISTRIBUIDOR],'RESUMEN 1'!B26) -> 0 | J26: =SUMIFS(Tabla6[TOTAL],Tabla6[MES],'RESUMEN 1'!J5,Tabla6[AÑO],'RESUMEN 1'!A5,Tabla6[DISTRIBUIDOR],'RESUMEN 1'!B26) -> 0 | K26: =SUMIFS(Tabla6[TOTAL],Tabla6[MES],'RESUMEN 1'!K5,Tabla6[AÑO],'RESUMEN 1'!A5,Tabla6[DISTRIBUIDOR],'RESUMEN 1'!B26) -> 0 | L26: =SUMIFS(Tabla6[TOTAL],Tabla6[MES],'RESUMEN 1'!L5,Tabla6[AÑO],'RESUMEN 1'!A5,Tabla6[DISTRIBUIDOR],'RESUMEN 1'!B26) -> 0 | M26: =SUMIFS(Tabla6[TOTAL],Tabla6[MES],'RESUMEN 1'!M5,Tabla6[AÑO],'RESUMEN 1'!A5,Tabla6[DISTRIBUIDOR],'RESUMEN 1'!B26) -> 0 | N26: =SUMIFS(Tabla6[TOTAL],Tabla6[MES],'RESUMEN 1'!N5,Tabla6[AÑO],'RESUMEN 1'!A5,Tabla6[DISTRIBUIDOR],'RESUMEN 1'!B26) -> 0
A27: POR PAGAR | B27: OPTEC | C27: =SUMIFS(Tabla6[TOTAL],Tabla6[MES],'RESUMEN 1'!C5,Tabla6[AÑO],'RESUMEN 1'!A5,Tabla6[DISTRIBUIDOR],'RESUMEN 1'!B27) -> 480.59 | D27: =SUMIFS(Tabla6[TOTAL],Tabla6[MES],'RESUMEN 1'!D5,Tabla6[AÑO],'RESUMEN 1'!A5,Tabla6[DISTRIBUIDOR],'RESUMEN 1'!B27) -> 280.6 | E27: =SUMIFS(Tabla6[TOTAL],Tabla6[MES],'RESUMEN 1'!E5,Tabla6[AÑO],'RESUMEN 1'!A5,Tabla6[DISTRIBUIDOR],'RESUMEN 1'!B27) -> 0 | F27: =SUMIFS(Tabla6[TOTAL],Tabla6[MES],'RESUMEN 1'!F5,Tabla6[AÑO],'RESUMEN 1'!A5,Tabla6[DISTRIBUIDOR],'RESUMEN 1'!B27) -> 0 | G27: =SUMIFS(Tabla6[TOTAL],Tabla6[MES],'RESUMEN 1'!G5,Tabla6[AÑO],'RESUMEN 1'!A5,Tabla6[DISTRIBUIDOR],'RESUMEN 1'!B27) -> 0 | H27: =SUMIFS(Tabla6[TOTAL],Tabla6[MES],'RESUMEN 1'!H5,Tabla6[AÑO],'RESUMEN 1'!A5,Tabla6[DISTRIBUIDOR],'RESUMEN 1'!B27) -> 0 | I27: =SUMIFS(Tabla6[TOTAL],Tabla6[MES],'RESUMEN 1'!I5,Tabla6[AÑO],'RESUMEN 1'!A5,Tabla6[DISTRIBUIDOR],'RESUMEN 1'!B27) -> 0 | J27: =SUMIFS(Tabla6[TOTAL],Tabla6[MES],'RESUMEN 1'!J5,Tabla6[AÑO],'RESUMEN 1'!A5,Tabla6[DISTRIBUIDOR],'RESUMEN 1'!B27) -> 0 | K27: =SUMIFS(Tabla6[TOTAL],Tabla6[MES],'RESUMEN 1'!K5,Tabla6[AÑO],'RESUMEN 1'!A5,Tabla6[DISTRIBUIDOR],'RESUMEN 1'!B27) -> 0 | L27: =SUMIFS(Tabla6[TOTAL],Tabla6[MES],'RESUMEN 1'!L5,Tabla6[AÑO],'RESUMEN 1'!A5,Tabla6[DISTRIBUIDOR],'RESUMEN 1'!B27) -> 0 | M27: =SUMIFS(Tabla6[TOTAL],Tabla6[MES],'RESUMEN 1'!M5,Tabla6[AÑO],'RESUMEN 1'!A5,Tabla6[DISTRIBUIDOR],'RESUMEN 1'!B27) -> 0 | N27: =SUMIFS(Tabla6[TOTAL],Tabla6[MES],'RESUMEN 1'!N5,Tabla6[AÑO],'RESUMEN 1'!A5,Tabla6[DISTRIBUIDOR],'RESUMEN 1'!B27) -> 0
A28: POR PAGAR | B28: PECSA | C28: =SUMIFS(Tabla6[TOTAL],Tabla6[MES],'RESUMEN 1'!C5,Tabla6[AÑO],'RESUMEN 1'!A5,Tabla6[DISTRIBUIDOR],'RESUMEN 1'!B28) -> 302.44 | D28: =SUMIFS(Tabla6[TOTAL],Tabla6[MES],'RESUMEN 1'!D5,Tabla6[AÑO],'RESUMEN 1'!A5,Tabla6[DISTRIBUIDOR],'RESUMEN 1'!B28) -> 282.12 | E28: =SUMIFS(Tabla6[TOTAL],Tabla6[MES],'RESUMEN 1'!E5,Tabla6[AÑO],'RESUMEN 1'!A5,Tabla6[DISTRIBUIDOR],'RESUMEN 1'!B28) -> 0 | F28: =SUMIFS(Tabla6[TOTAL],Tabla6[MES],'RESUMEN 1'!F5,Tabla6[AÑO],'RESUMEN 1'!A5,Tabla6[DISTRIBUIDOR],'RESUMEN 1'!B28) -> 0 | G28: =SUMIFS(Tabla6[TOTAL],Tabla6[MES],'RESUMEN 1'!G5,Tabla6[AÑO],'RESUMEN 1'!A5,Tabla6[DISTRIBUIDOR],'RESUMEN 1'!B28) -> 0 | H28: =SUMIFS(Tabla6[TOTAL],Tabla6[MES],'RESUMEN 1'!H5,Tabla6[AÑO],'RESUMEN 1'!A5,Tabla6[DISTRIBUIDOR],'RESUMEN 1'!B28) -> 0 | I28: =SUMIFS(Tabla6[TOTAL],Tabla6[MES],'RESUMEN 1'!I5,Tabla6[AÑO],'RESUMEN 1'!A5,Tabla6[DISTRIBUIDOR],'RESUMEN 1'!B28) -> 0 | J28: =SUMIFS(Tabla6[TOTAL],Tabla6[MES],'RESUMEN 1'!J5,Tabla6[AÑO],'RESUMEN 1'!A5,Tabla6[DISTRIBUIDOR],'RESUMEN 1'!B28) -> 0 | K28: =SUMIFS(Tabla6[TOTAL],Tabla6[MES],'RESUMEN 1'!K5,Tabla6[AÑO],'RESUMEN 1'!A5,Tabla6[DISTRIBUIDOR],'RESUMEN 1'!B28) -> 0 | L28: =SUMIFS(Tabla6[TOTAL],Tabla6[MES],'RESUMEN 1'!L5,Tabla6[AÑO],'RESUMEN 1'!A5,Tabla6[DISTRIBUIDOR],'RESUMEN 1'!B28) -> 0 | M28: =SUMIFS(Tabla6[TOTAL],Tabla6[MES],'RESUMEN 1'!M5,Tabla6[AÑO],'RESUMEN 1'!A5,Tabla6[DISTRIBUIDOR],'RESUMEN 1'!B28) -> 0 | N28: =SUMIFS(Tabla6[TOTAL],Tabla6[MES],'RESUMEN 1'!N5,Tabla6[AÑO],'RESUMEN 1'!A5,Tabla6[DISTRIBUIDOR],'RESUMEN 1'!B28) -> 0
A29: POR PAGAR | B29: DANNA | C29: =SUMIFS(Tabla6[TOTAL],Tabla6[MES],'RESUMEN 1'!C5,Tabla6[AÑO],'RESUMEN 1'!A5,Tabla6[DISTRIBUIDOR],'RESUMEN 1'!B29) -> 0
A30: POR PAGAR | B30: BRYAM
A31: POR PAGAR | B31: DANNA
A32: POR PAGAR | B32: DANNA
B39: Saldo Mensual | C39: =+C6-C15 -> 4343.71 | D39: =+D6-D15 -> 676.87 | E39: =+E6-E15 -> 0 | F39: =+F6-F15 -> 0 | G39: =+G6-G15 -> 0 | H39: =+H6-H15 -> 0 | I39: =+I6-I15 -> 0 | J39: =+J6-J15 -> 0 | ... N39: =+N6-N15 -> 0
B41: Saldo Acumulado | C41: =+C39 -> 4343.71 | D41: =C41+D39 -> 5020.58 | E41: =D41+E39 -> 5020.58 | F41: =E41+F39 -> 5020.58 | G41: =F41+G39 -> 5020.58 | H41: =G41+H39 -> 5020.58 | I41: =H41+I39 -> 5020.58 | J41: =I41+J39 -> 5020.58 | K41: =J41+K39 -> 5020.58 | ... N41: =M41+N39 -> 5020.58

Sheet REPORTE CAJA
A1: RESUMEN DE MOVIMIENTOS
A2: FECHA | B2: NOMBRE | C2: APELLIDO | D2: PRODUCTO | E2: CANTIDAD | F2: PRECIO | G2: INGRESO | H2: DESCRIPCION | I2: OBSERVACION | J2: TIPO DE PAGO | K2: MES | L2: AÑO | M2: ORDEN | N2: SOFFI
A3: 45946 | B3: EDGAR | C3: PEÑAFIEL | D3: LENTES | E3: 1 | F3: 35 | G3: =E3*F3 -> 35 | H3: CANCELACION | J3: EFECTIVO | K3: =UPPER(TEXT(A3,"MMMM")) -> OCTUBRE | L3: =+YEAR(A3) -> 2025 | M3: 595 | N3: RV330
A4: 45946 | B4: MIGUEL | C4: MOROCHO | D4: LENTES | E4: 1 | F4: 45 | G4: =E4*F4 -> 45 | H4: CANCELACION | J4: EFECTIVO | K4: =UPPER(TEXT(A4,"MMMM")) -> OCTUBRE | L4: =+YEAR(A4) -> 2025 | M4: 596 | N4: RV331
A5: 45946 | B5: BELGICA | C5: GARCIA | D5: LENTES | E5: 1 | F5: 10 | G5: =E5*F5 -> 10 | H5: ABONO | J5: EFECTIVO | K5: =UPPER(TEXT(A5,"MMMM")) -> OCTUBRE | L5: =+YEAR(A5) -> 2025 | M5: 597 | N5: IT456
A6: 45946 | B6: DAN | C6: SAMANIEGO | D6: LENTES | E6: 1 | F6: 100 | G6: =E6*F6 -> 100 | H6: ABONO | J6: EFECTIVO | K6: =UPPER(TEXT(A6,"MMMM")) -> OCTUBRE | L6: =+YEAR(A6) -> 2025 | M6: 598 | N6: IT453
A7: 45946 | B7: MARCO | C7: MOCHA | D7: LENTES | E7: 1 | F7: 20 | G7: =E7*F7 -> 20 | H7: ABONO | J7: EFECTIVO | K7: =UPPER(TEXT(A7,"MMMM")) -> OCTUBRE | L7: =+YEAR(A7) -> 2025 | M7: 599 | N7: IT454
A8: 45946 | B8: BRYAN | C8: VIZHÑAY | D8: LENTES | E8: 1 | F8: 60 | G8: =E8*F8 -> 60 | H8: CANCELACION | J8: EFECTIVO | K8: =UPPER(TEXT(A8,"MMMM")) -> OCTUBRE | L8: =+YEAR(A8) -> 2025 | M8: 600 | N8: IT455
B9: 45946 | C9: COMPRAS | D9: OTROS | E9: 2 | F9: 1.5 | G9: =F9*E9 -> 3 | H9: FUNDAS DE BASURA FLOREADAS | J9: =UPPER(TEXT(B9,"MMMM")) -> OCTUBRE | K9: =+YEAR(B9) -> 2025 | L9: EFECTIVO | M9: ET606
B10: 45946 | C10: COMPRAS | D10: OTROS | E10: 1 | F10: 1 | G10: =F10*E10 -> 1 | H10: FUNDAS DE BASURA NEGRAS | J10: =UPPER(TEXT(B10,"MMMM")) -> OCTUBRE | K10: =+YEAR(B10) -> 2025 | L10: EFECTIVO | M10: ET606
B11: FECHA | C11: CUENTA | D11: DISTRIBUIDOR | E11: CANTIDAD | F11: PRECIO | G11: EGRESO | H11: DETALLE ADICIONAL | I11: NO. DOCUMENTO | J11: MES | K11: AÑO | L11: TIPO DE PAGO | M11: SOFFI
A12: 45946 | B12: ESTEBAN | C12: MATUTE | D12: CERTIFICADO | E12: 1 | F12: 5 | G12: =E12*F12 -> 5 | H12: CANCELACION | J12: EFECTIVO | K12: =UPPER(TEXT(A12,"MMMM")) -> OCTUBRE | L12: =+YEAR(A12) -> 2025 | N12: RV337
G13: =E13*F13 -> 0 | K13: =UPPER(TEXT(A13,"MMMM")) -> ENERO | L13: =+YEAR(A13) -> 1900
E16: INGRESOS | F16: =SUM(F3:F9) -> 271.5
E17: EGRESOS | F17: =SUM(G12:G13) -> 5 | H17: RECIBI CONFORME
H18: FECHA
D19: TOTAL ENTREGADO | F19: =F16-F17 -> 266.5
A21: RESUMEN DE MOVIMIENTOS
A22: FECHA | B22: NOMBRE | C22: APELLIDO | D22: PRODUCTO | E22: CANTIDAD | F22: PRECIO | G22: INGRESO | H22: DESCRIPCION | I22: OBSERVACION | J22: TIPO DE PAGO | K22: MES | L22: AÑO | M22: ORDEN | N22: SOFFI
A23: 45947 | B23: JOSE | C23: MAITE | D23: LENTES | E23: 1 | F23: 300 | G23: =E23*F23 -> 300 | H23: CANCELACION | J23: EFECTIVO | K23: =UPPER(TEXT(A23,"MMMM")) -> OCTUBRE | L23: =+YEAR(A23) -> 2025 | M23: 553
A24: 45947 | B24: HUGO | C24: CAJAMARCA | D24: LENTES | E24: 1 | F24: 185 | G24: =E24*F24 -> 185 | H24: CANCELACION | J24: EFECTIVO | K24: =UPPER(TEXT(A24,"MMMM")) -> OCTUBRE | L24: =+YEAR(A24) -> 2025 | M24: 594 | N24: FCE345
A25: 45947 | B25: BELGICA | C25: GARCIA | D25: LENTES | E25: 1 | F25: 35 | G25: =E25*F25 -> 35 | H25: CANCELACION | J25: EFECTIVO | K25: =UPPER(TEXT(A25,"MMMM")) -> OCTUBRE | L25: =+YEAR(A25) -> 2025 | M25: 597 | N25: RV339
A26: 45947 | B26: DAN | C26: SAMANIEGO | D26: LENTES | E26: 1 | F26: 20 | G26: =E26*F26 -> 20 | H26: CANCELACION | J26: EFECTIVO | K26: =UPPER(TEXT(A26,"MMMM")) -> OCTUBRE | L26: =+YEAR(A26) -> 2025 | M26: 598 | N26: RV338
A27: 45947 | B27: FABIAN | C27: MOSQUERA | D27: LENTES | E27: 1 | F27: 0 | G27: =E27*F27 -> 0 | H27: ABONO | J27: EFECTIVO | K27: =UPPER(TEXT(A27,"MMMM")) -> OCTUBRE | L27: =+YEAR(A27) -> 2025 | M27: 601
A28: 45947 | B28: HILDA LEONOR | C28: ANDRADE REYES | D28: LENTES | E28: 1 | F28: 5 | G28: =E28*F28 -> 5 | H28: ABONO | J28: EFECTIVO | K28: =UPPER(TEXT(A28,"MMMM")) -> OCTUBRE | L28: =+YEAR(A28) -> 2025 | M28: 602 | N28: IT458
B30: FECHA | C30: CUENTA | D30: DISTRIBUIDOR | E30: CANTIDAD | F30: PRECIO | G30: EGRESO | H30: DETALLE ADICIONAL | I30: NO. DOCUMENTO | J30: MES | K30: AÑO | L30: TIPO DE PAGO | M30: SOFFI
B31: 45947 | C31: COMPRAS | D31: OTROS | E31: 1 | F31: 0.5 | G31: =Tabla8[[#This Row],[CANTIDAD]]*Tabla8[[#This Row],[PRECIO]] -> 0.75 | H31: BRUJITA | J31: =UPPER(TEXT(B31,"MMMM")) -> OCTUBRE | K31: =+YEAR(B31) -> 2025 | L31: EFECTIVO | M31: ET607
B32: 45947 | C32: COMPRAS | D32: OTROS | E32: 1 | F32: 0.25 | G32: =Tabla8[[#This Row],[CANTIDAD]]*Tabla8[[#This Row],[PRECIO]] -> 40 | H32: LIMON | J32: =UPPER(TEXT(B32,"MMMM")) -> OCTUBRE | K32: =+YEAR(B32) -> 2025 | L32: EFECTIVO | M32: ET608
E34: INGRESO | F34: =SUM(F23:F28) -> 545
E35: EGRESO | F35: =SUM(F31:F32) -> 0.75
H36: RECIBI CONFORME
D37: TOTAL ENTREGADO | F37: =F34-F35 -> 544.25 | H37: FECHA
A40: RESUMEN DE MOVIMIENTOS
A41: FECHA | B41: NOMBRE | C41: APELLIDO | D41: PRODUCTO | E41: CANTIDAD | F41: PRECIO | G41: INGRESO | H41: DESCRIPCION | I41: OBSERVACION | J41: TIPO DE PAGO | K41: MES | L41: AÑO | M41: ORDEN | N41: SOFFI
A42: 45951 | B42: CARLOS | C42: LIMA | D42: LENTES | E42: 1 | F42: 130 | G42: =E42*F42 -> 130 | H42: CANCELACION | I42: RETIRA LENTES | J42: EFECTIVO | K42: =UPPER(TEXT(A42,"MMMM")) -> OCTUBRE | L42: =+YEAR(A42) -> 2025 | M42: 583
A43: 45948 | B43: MARCO | C43: MOCHA | D43: LENTES | E43: 1 | F43: 20 | G43: 20 | H43: CANCELACION | J43: EFECTIVO | K43: OCTUBRE | L43: 2025 | M43: 599
A44: 45950 | B44: JOSE | C44: ARPI | D44: LENTES | E44: 1 | F44: 150 | G44: 150 | H44: ABONO | J44: JEP BRYAM | K44: OCTUBRE | L44: 2025 | M44: 603 | N44: IT472
A45: 45950 | B45: FRANKLIN | C45: QUITUIZACA | D45: LENTES | E45: 1 | F45: 30 | G45: 30 | H45: ABONO | J45: EFECTIVO | K45: OCTUBRE | L45: 2025 | M45: 604 | N45: IT462
A46: 45950 | B46: MARTHA LUCIA | C46: ALVAREZ | D46: LENTES | E46: 1 | F46: 20 | G46: 20 | H46: ABONO | J46: EFECTIVO | K46: OCTUBRE | L46: 2025 | M46: 605 | N46: IT461
A47: 45950 | B47: JORGE LUIS | C47: LEON | D47: LENTES | E47: 1 | F47: 50 | G47: 50 | H47: ABONO | J47: EFECTIVO | K47: OCTUBRE | L47: 2025 | M47: 606 | N47: IT460
...

Sheet RESUMEN 2

Sheet TABLA
A10: Etiquetas de fila
A11: LENTES
A12: CERTIFICADO
A13: Total general

Sheet Hoja1

Sheet CUENTAS CONTABLES
A4: CUENTAS DE INGRESO | C4: CUENTAS DE GASTO | E4: PRODUCTO | G4: TIPO DE PAGO | I4: DISTRIBUIDOR | K4: ESTADO
A5: ABONO | C5: BISEL Y LUNAS | E5: LENTES | G5: EFECTIVO | I5: ALEPSA | K5: POR PAGAR
A6: CANCELACION | C6: MOTORIZADO | E6: CERTIFICADO | G6: TARJETA | I6: IMPORTLENTS | K6: PAGADO
C7: COMIDA | E7: CARRERAS | G7: JEP DANNA | I7: DELIVERY
C8: DEPOSITO | E8: ALIMENTACION | G8: PICHINCHA | I8: PERSONAL
C9: LUZ | E9: DISTRIBUIDORA | G9: PRODUBANCO | I9: OPTICA
C10: AGUA | E10: ACCESORIOS | G10: JARDIN AZUAYO | I10: JEP
C11: COMPRAS | G11: JEP BRYAM | I11: PICHINCHA
C12: ARRIENDO | G12: BRYAM | I12: PRODUBANCO
C13: DEPOSITO | G13: DE UNA | I13: JARDIN AZUAYO
C14: BRYAM | G14: DANNA | I14: OTROS
C15: DANNA | I15: OPTEC
C16: OTROS | I16: PECSA
I17: PROVISION LENS
I18: BRYAM
I19: DANNA
I20: DELBAK
I21: PROVISION CUENCA
I22: TECNILENTS
I23: ANDINA
I24: GUARTAZACA
I25: RESTREPO
